<?xml version='1.0'?>
<sdf version='1.4'>
  <model name='SMORES8Jack_gripper'>
	<static>false</static>
  <pose>0 0 .05 0 0 0</pose>
	<!--pose>0 0 .1 0 0 0</pose-->

    <link name='CircuitHolder'>
      <pose>0 0 0 0 0 0</pose>
      <inertial>
        <!--pose>0.00799044 -0.00824713 0.00675345 0 -0 0</pose-->
        <pose>0 -0.00824713 0 0 0 0</pose>
        <mass>0.309551</mass>
        <inertia>
          <ixx>0.000152716</ixx>
          <ixy>0</ixy>
          <ixz>0</ixz>
          <iyy>0.000166672</iyy>
          <iyz>0</iyz>
          <izz>0.000206589</izz>
        </inertia>
      </inertial>
      <collision name='CircuitHolder_collision'>
        <pose>0.03605 0.02985 -0.029675 1.5707963 0 -1.5707963</pose>
        <geometry>
          <mesh>
            <scale>1 1 1</scale>
            <uri>model://SMORES8Jack/meshes/CircuitHolderNew.STL</uri>
          </mesh>
        </geometry>
      </collision>
      <visual name='CircuitHolder_visual'>
        <pose>0 0 0 0 0 0</pose>
        <geometry>
          <mesh>
            <scale>1 1 1</scale>
            <uri>model://SMORES8Jack/meshes/CircuitHolder.STL</uri>
          </mesh>
        </geometry>
				<material>
					<ambient>0 0 0 1</ambient>
				</material>
      </visual>
      
      <visual name='CircuitKey_visual'>
        <pose>0 0 0 0 0 0</pose>
        <geometry>
          <mesh>
            <scale>1 1 1</scale>
            <uri>model://SMORES8Jack/meshes/CircuitKey.STL</uri>
          </mesh>
        </geometry>
				<material>
					<ambient>0.9098 0.4431 0.0314 1</ambient>
				</material>
      </visual>

      <visual name='CircuitPart_visual'>
        <pose>0 0 0 0 0 0</pose>
        <geometry>
          <mesh>
            <scale>1 1 1</scale>
            <uri>model://SMORES8Jack/meshes/CircuitPart.STL</uri>
          </mesh>
        </geometry>
				<material>
					<ambient>0.956862745098039 0.956862745098039 0.956862745098039 1</ambient>
				</material>
      </visual>
    </link>

		<link name='UHolderBody'>
      <pose>0 0 0 0 0 0</pose>
			<inertial>
        <pose>0 0.0306753 0 0 0 0</pose>
        <mass>0.127498</mass>
        <inertia>
          <ixx>0.000145026</ixx>
          <ixy>0</ixy>
          <ixz>0</ixz>
          <iyy>0.000207429</iyy>
          <iyz>0</iyz>
          <izz>0.000191183</izz>
        </inertia>
      </inertial>
      <collision name='UHolderBody_collision'>
        <pose>0.04265 0.04915 -0.04395 1.5707963 0 -1.5707963</pose>
        <geometry>
          <mesh>
            <scale>1 1 1</scale>
            <uri>model://SMORES8Jack/meshes/UHolderNew.STL</uri>
          </mesh>
        </geometry>
        <!-- The surface prperties of the U shape holder-->
        <surface>
          <friction>
            <ode>
              <mu>0.35</mu>
              <mu2>0.35</mu2>
            </ode>
          </friction>
        </surface>
      </collision>
      <visual name='UHolderBody_visual'>
        <pose>0 0 0 0 0 0</pose>
        <geometry>
          <mesh>
            <scale>1 1 1</scale>
            <uri>model://SMORES8Jack/meshes/UHolderBody.STL</uri>
          </mesh>
        </geometry>
				<material>
					<ambient>0 0 0 1</ambient>
				</material>
      </visual>

      <visual name='UMagAndGears_visual'>
        <pose>0 0 0 0 0 0</pose>
        <geometry>
          <mesh>
            <scale>1 1 1</scale>
            <uri>model://SMORES8Jack/meshes/UMagAndGears.STL</uri>
          </mesh>
        </geometry>
				<material>
					<ambient>0.956862745098039 0.956862745098039 0.956862745098039 1</ambient>
				</material>
      </visual>

      <visual name='UGreenPad_visual'>
        <pose>0 0 0 0 0 0</pose>
        <geometry>
          <mesh>
            <scale>1 1 1</scale>
            <uri>model://SMORES8Jack/meshes/UGreenPad.STL</uri>
          </mesh>
        </geometry>
				<material>
					<ambient>0 1 0 1</ambient>
				</material>
      </visual>

      <visual name='URedPad_visual'>
        <pose>0 0 0 0 -0 0</pose>
        <geometry>
          <mesh>
            <scale>1 1 1</scale>
            <uri>model://SMORES8Jack/meshes/URedPad.STL</uri>
          </mesh>
        </geometry>
				<material>
					<ambient>1 0 0 1</ambient>
				</material>
      </visual>

      <sensor name='UHolder_contact' type='contact'>
          <contact>
            <collision>UHolderBody_collision</collision>
          </contact>
          <plugin name="my_plugin" filename="plugins/libcontact.so"/>
      </sensor>

    </link>

		<link name='FrontWheel'>
      <pose>0 0 0 0 0 0</pose>
			<inertial>
        <pose>0 -0.0436519 0 0 0 0</pose>
        <mass>0.045716</mass>
        <inertia>
          <ixx>1.94691e-05</ixx>
          <ixy>0</ixy>
          <ixz>0</ixz>
          <iyy>3.74262e-05</iyy>
          <iyz>0</iyz>
          <izz>1.94691e-05</izz>
        </inertia>
      </inertial>
      <collision name='FrontWheel_collision'>
        <pose>0.04202 -0.04913 -0.04202 0 0 1.5707963</pose>
        <geometry>
          <mesh>
            <scale>1 1 1</scale>
            <uri>model://SMORES8Jack/meshes/FrontWheelThin.STL</uri>
          </mesh>
        </geometry>
        <!-- Properties of the front wheel-->
        <surface>
          <friction>
            <ode>
              <mu>0.75</mu>
              <mu2>0.75</mu2>
            </ode>
          </friction>
        </surface>
      </collision>
      <visual name='FrontWheel_visual'>
        <pose>0 0 0 0 0 0</pose>
        <geometry>
          <mesh>
            <scale>1 1 1</scale>
            <uri>model://SMORES8Jack/meshes/FrontWheel.STL</uri>
          </mesh>
        </geometry>
				<material>
					<ambient>0.7 0.7 0.7 1</ambient>
				</material>
      </visual>
     
      <visual name='CenterMag2_visual'>
        <pose>0 0 0 0 -0 0</pose>
        <geometry>
          <mesh>
            <scale>1 1 1</scale>
            <uri>model://SMORES8Jack/meshes/CenterMag2.STL</uri>
          </mesh>
        </geometry>
				<material>
					<ambient>0.956862745098039 0.956862745098039 0.956862745098039 1</ambient>
				</material>
      </visual>
			
      <visual name='RedPad2_visual'>
        <pose>0 0 0 0 -0 0</pose>
        <geometry>
          <mesh>
            <scale>1 1 1</scale>
            <uri>model://SMORES8Jack/meshes/RedPad2.STL</uri>
          </mesh>
        </geometry>
				<material>
					<ambient>1 0 0 1</ambient>
				</material>
      </visual>

      <visual name='GreenPad2_visual'>
        <pose>0 0 0 0 0 0</pose>
        <geometry>
          <mesh>
            <scale>1 1 1</scale>
            <uri>model://SMORES8Jack/meshes/GreenPad2.STL</uri>
          </mesh>
        </geometry>
				<material>
					<ambient>0 1 0 1</ambient>
				</material>
      </visual>

      <sensor name='front_contact' type='contact'>
          <contact>
            <collision>FrontWheel_collision</collision>
          </contact>
          <plugin name="my_plugin" filename="plugins/libcontact.so"/>
      </sensor>
    </link>

		<link name='LeftWheel'>
      <pose>0 0 0 0 0 0</pose>
			<inertial>
        <pose>0.0457825 0 0 0 -0 0</pose>
        <mass>0.0372637</mass>
        <inertia>
          <ixx>3.37995e-05</ixx>
          <ixy>0</ixy>
          <ixz>0</ixz>
          <iyy>1.71576e-05</iyy>
          <iyz>0</iyz>
          <izz>1.71576e-05</izz>
        </inertia>
      </inertial>
      <collision name='LeftWheel_collision'>
        <pose>0.04312 -0.045275 -0.045275 0 0 0</pose>
        <geometry>
          <mesh>
            <scale>1 1 1</scale>
            <uri>model://SMORES8Jack/meshes/MainWheelNewThick.STL</uri>
          </mesh>
        </geometry>
        <!-- Surface Property of material -->
        <!-- The friction coefficient is large because of the rubber band around the wheel-->
        <surface>
          <friction>
            <ode>
              <mu>1</mu>
              <mu2>1</mu2>
            </ode>
          </friction>
        </surface>
      </collision>
      <visual name='LeftWheel_visual'>
        <pose>0 0 0 0 0 0</pose>
        <geometry>
          <mesh>
            <scale>1 1 1</scale>
            <uri>model://SMORES8Jack/meshes/MainWheel.STL</uri>
          </mesh>
        </geometry>
				<material>
					<ambient>0 0.50588 1 1</ambient>
				</material>
      </visual>
	
      <visual name='LeftMagneticBars_visual'>
        <pose>0 0 0 0 -0 0</pose>
        <geometry>
          <mesh>
            <scale>1 1 1</scale>
            <uri>model://SMORES8Jack/meshes/MagneticBars.STL</uri>
          </mesh>
        </geometry>
				<material>
					<ambient>0.956862745098039 0.956862745098039 0.956862745098039 1</ambient>
				</material>
      </visual>

      <visual name='LeftRedPad_visual'>
        <pose>0 0 0 0 0 0</pose>
        <geometry>
          <mesh>
            <scale>1 1 1</scale>
            <uri>model://SMORES8Jack/meshes/RedPad.STL</uri>
          </mesh>
        </geometry>
				<material>
					<ambient>1 0 0 1</ambient>
				</material>
      </visual>

      <visual name='LeftGreenPad_visual'>
        <pose>0 0 0 0 0 0</pose>
        <geometry>
          <mesh>
            <scale>1 1 1</scale>
            <uri>model://SMORES8Jack/meshes/GreenPad.STL</uri>
          </mesh>
        </geometry>
				<material>
					<ambient>0 1 0 1</ambient>
				</material>
      </visual>

      <sensor name='LeftWheel_contact' type='contact'>
          <contact>
            <collision>LeftWheel_collision</collision>
          </contact>
          <plugin name="my_plugin" filename="plugins/libcontact.so"/>
      </sensor>

    </link>

		<link name='RightWheel'>
      <pose>0 0 0 0 0 3.141593</pose>
			<inertial>
        <pose>-0.0457825 0 0 0 -0 0</pose>
        <mass>0.0372637</mass>
        <inertia>
          <ixx>3.37995e-05</ixx>
          <ixy>0</ixy>
          <ixz>0</ixz>
          <iyy>1.71576e-05</iyy>
          <iyz>0</iyz>
          <izz>1.71576e-05</izz>
        </inertia>
      </inertial>
      <collision name='RightWheel_collision'>
        <pose>0.04912 0.045275 -0.045275 0 0 3.1415926</pose>
        <geometry>
          <mesh>
            <scale>1 1 1</scale>
            <uri>model://SMORES8Jack/meshes/MainWheelNewThick.STL</uri>
          </mesh>
        </geometry>
        <!-- Surface Property of material -->
        <!-- The friction coefficient is large because of the rubber band around the wheel-->
        <surface>
          <friction>
            <ode>
              <mu>1</mu>
              <mu2>1</mu2>
            </ode>
          </friction>
        </surface>
      </collision>
      <visual name='RightWheel_visual'>
        <pose>0 0 0 0 0 0</pose>
        <geometry>
          <mesh>
            <scale>1 1 1</scale>
            <uri>model://SMORES8Jack/meshes/MainWheel.STL</uri>
          </mesh>
        </geometry>
				<material>
					<ambient>0.64706 0 0 1</ambient>
				</material>
      </visual>

      <visual name='RightMagneticBars_visual'>
        <pose>0 0 0 0 0 0</pose>
        <geometry>
          <mesh>
            <scale>1 1 1</scale>
            <uri>model://SMORES8Jack/meshes/MagneticBars.STL</uri>
          </mesh>
        </geometry>
				<material>
					<ambient>0.956862745098039 0.956862745098039 0.956862745098039 1</ambient>
				</material>
      </visual>

      <visual name='RightRedPad_visual'>
        <pose>0 0 0 0 0 0</pose>
        <geometry>
          <mesh>
            <scale>1 1 1</scale>
            <uri>model://SMORES8Jack/meshes/RedPad.STL</uri>
          </mesh>
        </geometry>
				<material>
					<ambient>1 0 0 1</ambient>
				</material>
      </visual>

      <visual name='RightGreenPad_visual'>
        <pose>0 0 0 0 -0 0</pose>
        <geometry>
          <mesh>
            <scale>1 1 1</scale>
            <uri>model://SMORES8Jack/meshes/GreenPad.STL</uri>
          </mesh>
        </geometry>
				<material>
					<ambient>0 1 0 1</ambient>
				</material>
      </visual>

      <sensor name='RightWheel_contact' type='contact'>
          <contact>
            <collision>RightWheel_collision</collision>
          </contact>
          <plugin name="my_plugin" filename="plugins/libcontact.so"/>
      </sensor>

    </link>

    <!-- Here come the joints -->
    
    <joint type="revolute" name="Right_wheel_hinge">
      <pose>0.045 0 0 0 0 0</pose>
      <child>RightWheel</child>
      <parent>UHolderBody</parent>
      <axis>
        <xyz>1 0 0</xyz>
        <!--velocity>2.4086</velocity-->
      </axis>
      <physics>
        <ode>
          <max_force>1.2</max_force>
        </ode>
      </physics>
    </joint>
    <joint type="revolute" name="Left_wheel_hinge">
      <pose>0.045 0 0 0 0 0</pose>
      <child>LeftWheel</child>
      <parent>UHolderBody</parent>
      <axis>
        <xyz>1 0 0</xyz>
        <!--velocity>2.4086</velocity-->
      </axis>
      <physics>
        <ode>
          <max_force>1.2</max_force>
        </ode>
      </physics>
    </joint>
    <joint type="revolute" name="Front_wheel_hinge">
      <pose>0 -0.044 0 0 0 0</pose>
      <child>FrontWheel</child>
      <parent>CircuitHolder</parent>
      <axis>
        <xyz>0 1 0</xyz>
        <!--velocity>2.4086</velocity-->
      </axis>
      <physics>
        <ode>
          <max_force>2.3</max_force>
        </ode>
      </physics>
    </joint>
    <joint type="revolute" name="Center_hinge">
      <pose>0 0 0 0 0 0</pose>
      <child>UHolderBody</child>
      <parent>CircuitHolder</parent>
      <axis>
        <!--dynamics>
          <damping>0.20000</damping>
        </dynamics-->
        <xyz>1 0 0</xyz>
        <!--velocity>2.4086</velocity-->
        <limit>
          <lower>-1.5707963</lower>
          <upper>1.5707963</upper>
        </limit>
      </axis>
      <physics>
        <ode>
          <max_force>2.3</max_force>
        </ode>
      </physics>
    </joint>

    <plugin name="GripperController" filename="plugins/libGripperController.so"/>
  </model>
</sdf>
